<?xml version="1.0"?>
<robot name="simple_wheeled_robot">

  <!-- Barra horizontal -->
  <link name="bar">
    <visual>
    <origin rpy="0 0 0" xyz="0 0 -0.10" />
      <geometry>
        <box size="1.0 0.2 0.05"/>
      </geometry>
      <material name="red">
        <color rgba="1 0 0 1"/>
      </material>
    </visual>
    <collision>
    <origin rpy="0 0 0" xyz="0 0 -0.10" />
      <geometry>
        <box size="1.0 0.2 0.05"/>
      </geometry>
    </collision>
    <inertial>
      <mass value="5.0"/>
      <inertia ixx="0.1" ixy="0" ixz="0" iyy="0.1" iyz="0" izz="0.1"/>
    </inertial>
  </link>

  <!-- Rueda izquierda -->
  <link name="left_wheel">
    <visual>
      <geometry>
        <cylinder length="0.1" radius="0.5"/> <!-- Cilindro vertical que representa la rueda -->
      </geometry>
      <material name="black">
        <color rgba="0 0 0 1"/>
      </material>
    </visual>
    <collision>
      <geometry>
        <cylinder length="0.1" radius="0.5"/>
      </geometry>
    </collision>
    <inertial>
      <mass value="5.0"/>
      <inertia ixx="0.2" ixy="0" ixz="0" iyy="0.2" iyz="0" izz="0.2"/>
    </inertial>
  </link>

  <!-- Rueda derecha -->
  <link name="right_wheel">
    <visual>
      <geometry>
        <cylinder length="0.1" radius="0.5"/> <!-- Cilindro vertical que representa la rueda -->
      </geometry>
      <material name="black">
        <color rgba="0 0 0 1"/>
      </material>
    </visual>
    <collision>
      <geometry>
        <cylinder length="0.1" radius="0.5"/>
      </geometry>
    </collision>
    <inertial>
      <mass value="5.0"/>
      <inertia ixx="0.2" ixy="0" ixz="0" iyy="0.2" iyz="0" izz="0.2"/>
    </inertial>
  </link>

  <!-- Articulaciones revolutivas para conectar las ruedas a la barra, ajustando para que las ruedas estén verticales -->
  <joint name="left_wheel_joint" type="continuous">
    <parent link="bar"/>
    <child link="left_wheel"/>
    <origin xyz="-0.5 0 -0.1" rpy="0 1.57 0"/> <!-- Rotación de 90 grados (1.57 radianes) para hacer la rueda vertical -->
    <axis xyz="0 0 1"/> <!-- Eje de rotación ajustado para la articulación revolutiva -->
  </joint>

  <joint name="right_wheel_joint" type="continuous">
    <parent link="bar"/>
    <child link="right_wheel"/>
    <origin xyz="0.5 0 -0.1" rpy="0 1.57 0"/> <!-- Rotación de 90 grados (1.57 radianes) para hacer la rueda vertical -->
    <axis xyz="0 0 1"/> <!-- Eje de rotación ajustado para la articulación revolutiva -->
  </joint>

</robot>
