<?xml version="1.0"?>
<!-- created with Phobos 1.0.1 "Capricious Choutengan" -->
  <robot name="probando">

    <link name="Barra_principal">
      <inertial>
        <origin xyz="0 0 -0.5" rpy="0 0 0"/>
        <mass value="30.0"/>
        <inertia ixx="0.001" ixy="0" ixz="0" iyy="0.001" iyz="0" izz="0.001"/>
      </inertial>
      <visual name="Cube.001">
        <origin xyz="0 0 -0.11" rpy="0 0 0"/>
        <geometry>
          <box size="0.5 0.3 2.41"/>
        </geometry>
      </visual>
      <collision name="Cube.001">
        <origin xyz="0 0 -0.1" rpy="0 0 0"/>
        <geometry>
          <box size="0.5 0.3 2.41"/>
        </geometry>
      </collision>
    </link>

    <link name="Pinza_L">
      <inertial>
        <origin xyz="0 0 -0.03" rpy="0 0 0"/>
        <mass value="15.51"/>
        <inertia ixx="0.001" ixy="0" ixz="0" iyy="0.001" iyz="0" izz="0.001"/>
      </inertial>
      <visual name="Cube.005">
        <origin xyz="0 0 0" rpy="0 0 0"/>
        <geometry>
          <box size="0.45 0.61 0.02"/>
        </geometry>
      </visual>
      <collision name="Cube.005">
        <origin xyz="0 0 0" rpy="3.14159 0 0"/>
        <geometry>
          <box size="0.45 0.61 0.02"/>
        </geometry>
      </collision>
    </link>

    <link name="Pinza_R">
      <inertial>
        <origin xyz="0 0 0.15" rpy="0 0 0"/>
        <mass value="15.51"/>
        <inertia ixx="0.001" ixy="0" ixz="0" iyy="0.001" iyz="0" izz="0.001"/>
      </inertial>
      <visual name="Cube">
        <origin xyz="0 0 0" rpy="0 0 0"/>
        <geometry>
          <box size="0.45 0.61 0.02"/>
        </geometry>
        <material name="Material.002"/>
      </visual>
      <collision name="Cube">
        <origin xyz="0 0 0" rpy="0 0 0"/>
        <geometry>
          <box size="0.45 0.61 0.02"/>
        </geometry>
      </collision>
    </link>

    <link name="Untitled.002">
      <inertial>
        <origin xyz="0 0 0" rpy="0 0 0"/>
        <mass value="0.001"/>
        <inertia ixx="0.001" ixy="0" ixz="0" iyy="0.001" iyz="0" izz="0.001"/>
      </inertial>
      <visual name="Cube.004">
        <origin xyz="0 0 0" rpy="0 0 0"/>
        <geometry>
          <box size="0.9 0.61 0.11"/>
        </geometry>
      </visual>
      <collision name="Cube.004">
        <origin xyz="0 0 0" rpy="0 0 0"/>
        <geometry>
          <box size="0.9 0.61 0.11"/>
        </geometry>
      </collision>
    </link>

    <link name="barra_gira">
      <inertial>
        <origin xyz="0 0 0" rpy="0 0 0"/>
        <mass value="30.0"/>
        <inertia ixx="0.001" ixy="0" ixz="0" iyy="0.001" iyz="0" izz="0.001"/>
      </inertial>
      <visual name="Cube.002">
        <origin xyz="-0.90353 0 0" rpy="0 -1.5708 0"/>
        <geometry>
          <box size="0.5 0.30001 2.17"/>
        </geometry>
      </visual>
      <collision name="Cube.002">
        <origin xyz="-0.90353 0 0" rpy="0 -1.5708 0"/>
        <geometry>
          <box size="0.5 0.3 2.17"/>
        </geometry>
      </collision>
    </link>

    <link name="barra_pinza">
      <inertial>
        <origin xyz="0 0 0.15" rpy="0 0 0"/>
        <mass value="20.0"/>
        <inertia ixx="0.001" ixy="0" ixz="0" iyy="0.001" iyz="0" izz="0.001"/>
      </inertial>
      <visual name="Cube.003">
        <origin xyz="-0.05 -0.03 0.66272" rpy="0 0 0"/>
        <geometry>
          <box size="0.5 0.3 2.74"/>
        </geometry>
      </visual>
      <collision name="Cube.003">
        <origin xyz="-0.05 -0.03 0.66272" rpy="0 0 0"/>
        <geometry>
          <box size="0.5 0.3 2.7"/>
        </geometry>
      </collision>
    </link>

    <link name="coche">
      <inertial>
        <origin xyz="0 0 -0.0021" rpy="0 0 0"/>
        <mass value="10000.0"/>
        <inertia ixx="114.54339" ixy="2.59267" ixz="-7.60408" iyy="45.98467" iyz="7.01369" izz="128.17601"/>
      </inertial>
      <visual name="car">
        <origin xyz="0 0 0" rpy="0 0 0"/>
        <geometry>
          <mesh filename="../meshes/dae/Cube.dae" scale="1.0 1.715 0.78246"/>
        </geometry>
        <material name="Material"/>
      </visual>
      <collision name="car.000">
        <origin xyz="0 0 -0.0021" rpy="0 0 0"/>
        <geometry>
          <mesh filename="../meshes/dae/Cube.016.dae" scale="1.0 1.0 1.0"/>
        </geometry>
      </collision>
    </link>

    <link name="esfera">
      <inertial>
        <origin xyz="0 0 0" rpy="0 0 0"/>
        <mass value="30.0"/>
        <inertia ixx="0.001" ixy="0" ixz="0" iyy="0.001" iyz="0" izz="0.001"/>
      </inertial>
      <visual name="Sphere">
        <origin xyz="0 0 0" rpy="0 0 0"/>
        <geometry>
          <mesh filename="../meshes/dae/Sphere.dae" scale="0.5 0.5 0.5"/>
        </geometry>
      </visual>
      <collision name="Sphere">
        <origin xyz="0 0 0" rpy="0 0 0"/>
        <geometry>
          <sphere radius="0.5"/>
        </geometry>
      </collision>
    </link>

    <link name="rueda1">
      <inertial>
        <origin xyz="0 0 0" rpy="0 0 0"/>
        <mass value="10.0"/>
        <inertia ixx="0.18726" ixy="0" ixz="0" iyy="0.09682" iyz="0" izz="3.78202"/>
      </inertial>
      <visual name="rueda3.001">
        <origin xyz="0 0 0" rpy="0 0 0"/>
        <geometry>
          <mesh filename="../meshes/dae/Torus.007.dae" scale="0.4 0.4 1.0"/>
        </geometry>
        <material name="rueda"/>
      </visual>
      <collision name="rueda3.001.000">
        <origin xyz="0 0 0" rpy="0 0 0"/>
        <geometry>
          <mesh filename="../meshes/dae/Torus.001.dae" scale="1.0 1.0 1.0"/>
        </geometry>
      </collision>
    </link>

    <link name="rueda2">
      <inertial>
        <origin xyz="0 0 0" rpy="0 0 0"/>
        <mass value="10.0"/>
        <inertia ixx="1.17034" ixy="0" ixz="0" iyy="0.70986" iyz="0" izz="0.70986"/>
      </inertial>
      <visual name="rueda4.001">
        <origin xyz="0 0 0" rpy="0 0 0"/>
        <geometry>
          <mesh filename="../meshes/dae/Torus.008.dae" scale="0.4 0.4 1.0"/>
        </geometry>
        <material name="rueda"/>
      </visual>
      <collision name="rueda4.001.000">
        <origin xyz="0 0 0" rpy="0 0 0"/>
        <geometry>
          <mesh filename="../meshes/dae/Torus.000.dae" scale="1.0 1.0 1.0"/>
        </geometry>
      </collision>
    </link>

    <link name="rueda3">
      <inertial>
        <origin xyz="0 0 0" rpy="0 0 0"/>
        <mass value="10.0"/>
        <inertia ixx="1.17034" ixy="0" ixz="0" iyy="0.70986" iyz="0" izz="0.70986"/>
      </inertial>
      <visual name="rueda2.001">
        <origin xyz="0 0 0" rpy="0 0 0"/>
        <geometry>
          <mesh filename="../meshes/dae/Torus.003.dae" scale="0.4 0.4 1.0"/>
        </geometry>
        <material name="rueda"/>
      </visual>
      <collision name="rueda2.001.000">
        <origin xyz="0 0 0" rpy="0 0 0"/>
        <geometry>
          <mesh filename="../meshes/dae/Torus.004.dae" scale="1.0 1.0 1.0"/>
        </geometry>
      </collision>
    </link>

    <link name="rueda4">
      <inertial>
        <origin xyz="0 0 0" rpy="0 0 0"/>
        <mass value="10.0"/>
        <inertia ixx="1.17034" ixy="0" ixz="0" iyy="0.70986" iyz="0" izz="0.70986"/>
      </inertial>
      <visual name="rueda1.001">
        <origin xyz="0 0 0" rpy="0 0 0"/>
        <geometry>
          <mesh filename="../meshes/dae/Torus.006.dae" scale="0.4 0.4 1.0"/>
        </geometry>
        <material name="rueda"/>
      </visual>
      <collision name="rueda1.001.000">
        <origin xyz="0 0 0" rpy="0 0 0"/>
        <geometry>
          <mesh filename="../meshes/dae/Torus.002.dae" scale="1.0 1.0 1.0"/>
        </geometry>
      </collision>
    </link>

    <joint name="Barra_principal" type="prismatic">
      <origin xyz="0 -1.3 1.50313" rpy="0 0 0"/>
      <parent link="coche"/>
      <child link="Barra_principal"/>
      <axis xyz="0 0 1.0"/>
      <limit lower="-0.82" upper="0.5" effort="0" velocity="0"/>
    </joint>

    <joint name="Pinza_L" type="prismatic">
      <origin xyz="-0.39871 0.01611 -0.26543" rpy="3.14159 1.5708 0"/>
      <parent link="Untitled.002"/>
      <child link="Pinza_L"/>
      <axis xyz="0 0 1.0"/>
      <limit lower="1.92" upper="0.03" effort="0" velocity="0"/>
    </joint>

    <joint name="Pinza_R" type="prismatic">
      <origin xyz="0.44 0 -0.26" rpy="0 1.5708 0"/>
      <parent link="Untitled.002"/>
      <child link="Pinza_R"/>
      <axis xyz="0 0 1.0"/>
      <limit lower="-0.15" upper="0" effort="0" velocity="0"/>
    </joint>

    <joint name="Untitled.002" type="floating">
      <origin xyz="0 -0.01222 -0.7498" rpy="0 0 0"/>
      <parent link="barra_pinza"/>
      <child link="Untitled.002"/>
    </joint>

    <joint name="barra_gira" type="fixed">
      <origin xyz="0.03695 -0.02274 0.17047" rpy="1.5708 0 2.18414"/>
      <parent link="esfera"/>
      <child link="barra_gira"/>
    </joint>

    <joint name="barra_pinza" type="prismatic">
      <origin xyz="-1.83756 -0.82282 0.05342" rpy="-1.5708 -1.54235 0"/>
      <parent link="barra_gira"/>
      <child link="barra_pinza"/>
      <axis xyz="0 0 1.0"/>
      <limit lower="-1.17" upper="0.9" effort="0" velocity="0"/>
    </joint>

    <joint name="esfera" type="continuous">
      <origin xyz="-0.01713 0.0009 0.84188" rpy="0 0 0"/>
      <parent link="Barra_principal"/>
      <child link="esfera"/>
      <axis xyz="0 0 1.0"/>
      <limit effort="0" velocity="0"/>
    </joint>

    <joint name="rueda1" type="continuous">
      <origin xyz="1.5 1.47 -1.17" rpy="0 1.5708 0"/>
      <parent link="coche"/>
      <child link="rueda1"/>
      <axis xyz="0 0 1.0"/>
      <limit effort="0" velocity="0"/>
    </joint>

    <joint name="rueda2" type="continuous">
      <origin xyz="1.5 -1.47 -1.17" rpy="0 1.5708 0"/>
      <parent link="coche"/>
      <child link="rueda2"/>
      <axis xyz="0 0 1.0"/>
      <limit effort="0" velocity="0"/>
    </joint>

    <joint name="rueda3" type="continuous">
      <origin xyz="-1.5 1.47 -1.17" rpy="0 1.5708 0"/>
      <parent link="coche"/>
      <child link="rueda3"/>
      <axis xyz="0 0 1.0"/>
      <limit effort="0" velocity="0"/>
    </joint>

    <joint name="rueda4" type="continuous">
      <origin xyz="-1.5 -1.47 -1.17" rpy="0 1.5708 0"/>
      <parent link="coche"/>
      <child link="rueda4"/>
      <axis xyz="0 0 1.0"/>
      <limit effort="0" velocity="0"/>
    </joint>

    <material name="Material">
      <color rgba="0 0.8 0.58463 1.0"/>
    </material>

    <material name="Material.002">
      <color rgba="0.64 0.0277 0.35646 1.0"/>
    </material>

    <material name="rueda">
      <color rgba="0.08037 0.08037 0.08037 1.0"/>
    </material>

  </robot>
