<?xml version="1.0"?>
<!-- created with Phobos 1.0.1 "Capricious Choutengan" -->
  <robot name="robot_nuevo">

    <link name="Untitled">
      <inertial>
        <origin xyz="0 0 0" rpy="0 0 0"/>
        <mass value="0.001"/>
        <inertia ixx="0.001" ixy="0" ixz="0" iyy="0.001" iyz="0" izz="0.001"/>
      </inertial>
      <visual name="Cube.001">
        <origin xyz="0 0 -0.11" rpy="0 0 0"/>
        <geometry>
          <box size="0.5 0.3 2.41"/>
        </geometry>
      </visual>
      <collision name="Cube.001">
        <origin xyz="0 0 -0.1" rpy="0 0 0"/>
        <geometry>
          <box size="0.5 0.3 2.41"/>
        </geometry>
      </collision>
    </link>

    <link name="Untitled.001">
      <inertial>
        <origin xyz="0 0 0" rpy="0 0 0"/>
        <mass value="0.001"/>
        <inertia ixx="0.001" ixy="0" ixz="0" iyy="0.001" iyz="0" izz="0.001"/>
      </inertial>
      <visual name="Cube.005">
        <origin xyz="0 0 0" rpy="0 0 0"/>
        <geometry>
          <box size="0.45 0.61 0.02"/>
        </geometry>
      </visual>
      <collision name="Cube.005">
        <origin xyz="0 0 0" rpy="0 0 0"/>
        <geometry>
          <box size="0.45 0.61 0.02"/>
        </geometry>
      </collision>
    </link>

    <link name="Untitled.002">
      <inertial>
        <origin xyz="0 0 0" rpy="0 0 0"/>
        <mass value="0.001"/>
        <inertia ixx="0.001" ixy="0" ixz="0" iyy="0.001" iyz="0" izz="0.001"/>
      </inertial>
      <visual name="Cube.004">
        <origin xyz="0 0 0" rpy="0 0 0"/>
        <geometry>
          <box size="0.9 0.61 0.11"/>
        </geometry>
      </visual>
      <collision name="Cube.004">
        <origin xyz="0 0 0" rpy="0 0 0"/>
        <geometry>
          <box size="0.9 0.61 0.11"/>
        </geometry>
      </collision>
    </link>

    <link name="Untitled.003">
      <inertial>
        <origin xyz="0 0 0" rpy="0 0 0"/>
        <mass value="0.001"/>
        <inertia ixx="0.001" ixy="0" ixz="0" iyy="0.001" iyz="0" izz="0.001"/>
      </inertial>
      <visual name="Cube">
        <origin xyz="0 0 0" rpy="0 0 0"/>
        <geometry>
          <box size="0.45 0.61 0.02"/>
        </geometry>
      </visual>
      <collision name="Cube">
        <origin xyz="0 0 0" rpy="0 0 0"/>
        <geometry>
          <box size="0.45 0.61 0.02"/>
        </geometry>
      </collision>
    </link>

    <link name="Untitled.004">
      <inertial>
        <origin xyz="0 0 0" rpy="0 0 0"/>
        <mass value="0.001"/>
        <inertia ixx="0.001" ixy="0" ixz="0" iyy="0.001" iyz="0" izz="0.001"/>
      </inertial>
      <visual name="Cube.003">
        <origin xyz="-0.09 0 0.17272" rpy="0 0 0"/>
        <geometry>
          <box size="0.5 0.3 1.9"/>
        </geometry>
      </visual>
      <collision name="Cube.003">
        <origin xyz="-0.09 0 0.19272" rpy="0 0 0"/>
        <geometry>
          <box size="0.5 0.3 1.87"/>
        </geometry>
      </collision>
    </link>

    <link name="Untitled.005">
      <inertial>
        <origin xyz="0 0 0" rpy="0 0 0"/>
        <mass value="0.001"/>
        <inertia ixx="0.001" ixy="0" ixz="0" iyy="0.001" iyz="0" izz="0.001"/>
      </inertial>
      <visual name="Cube.002">
        <origin xyz="-1.57353 0 0" rpy="0 -1.5708 0"/>
        <geometry>
          <box size="0.5 0.3 3.25"/>
        </geometry>
      </visual>
      <collision name="Cube.002">
        <origin xyz="-1.57353 0 0" rpy="0 -1.5708 0"/>
        <geometry>
          <box size="0.5 0.3 3.25"/>
        </geometry>
      </collision>
    </link>

    <link name="Untitled.006">
      <inertial>
        <origin xyz="0 0 0" rpy="0 0 0"/>
        <mass value="0.001"/>
        <inertia ixx="0.001" ixy="0" ixz="0" iyy="0.001" iyz="0" izz="0.001"/>
      </inertial>
      <visual name="Sphere">
        <origin xyz="0 0 0" rpy="0 0 0"/>
        <geometry>
          <mesh filename="../meshes/dae/Sphere.dae" scale="0.5 0.5 0.5"/>
        </geometry>
      </visual>
      <collision name="Sphere">
        <origin xyz="0 0 0" rpy="0 0 0"/>
        <geometry>
          <sphere radius="0.5"/>
        </geometry>
      </collision>
    </link>

    <link name="coche">
      <inertial>
        <origin xyz="0 0 -0.0021" rpy="0 0 0"/>
        <mass value="10000.0"/>
        <inertia ixx="114.54339" ixy="2.59267" ixz="-7.60408" iyy="45.98467" iyz="7.01369" izz="128.17601"/>
      </inertial>
      <visual name="car">
        <origin xyz="0 0 0" rpy="0 0 0"/>
        <geometry>
          <mesh filename="../meshes/dae/Cube.dae" scale="1.0 1.715 0.78246"/>
        </geometry>
        <material name="Material"/>
      </visual>
      <collision name="car.000">
        <origin xyz="0 0 -0.0021" rpy="0 0 0"/>
        <geometry>
          <mesh filename="../meshes/dae/Cube.016.dae" scale="1.0 1.0 1.0"/>
        </geometry>
      </collision>
    </link>

    <link name="rueda1">
      <inertial>
        <origin xyz="0 0 0" rpy="0 0 0"/>
        <mass value="0.001"/>
        <inertia ixx="0.001" ixy="0" ixz="0" iyy="0.001" iyz="0" izz="0.001"/>
      </inertial>
      <visual name="rueda3.001">
        <origin xyz="0 0 0" rpy="0 0 0"/>
        <geometry>
          <mesh filename="../meshes/dae/Torus.007.dae" scale="0.4 0.4 1.0"/>
        </geometry>
      </visual>
      <collision name="rueda3.001.000">
        <origin xyz="0 0 0" rpy="0 0 0"/>
        <geometry>
          <mesh filename="../meshes/dae/Torus.001.dae" scale="1.0 1.0 1.0"/>
        </geometry>
      </collision>
    </link>

    <link name="rueda2">
      <inertial>
        <origin xyz="0 0 0" rpy="0 0 0"/>
        <mass value="0.001"/>
        <inertia ixx="0.001" ixy="0" ixz="0" iyy="0.001" iyz="0" izz="0.001"/>
      </inertial>
      <visual name="rueda4.001">
        <origin xyz="0 0 0" rpy="0 0 0"/>
        <geometry>
          <mesh filename="../meshes/dae/Torus.008.dae" scale="0.4 0.4 1.0"/>
        </geometry>
      </visual>
      <collision name="rueda4.001.000">
        <origin xyz="0 0 0" rpy="0 0 0"/>
        <geometry>
          <mesh filename="../meshes/dae/Torus.000.dae" scale="1.0 1.0 1.0"/>
        </geometry>
      </collision>
    </link>

    <link name="rueda3">
      <inertial>
        <origin xyz="0 0 0" rpy="0 0 0"/>
        <mass value="0.001"/>
        <inertia ixx="0.001" ixy="0" ixz="0" iyy="0.001" iyz="0" izz="0.001"/>
      </inertial>
      <visual name="rueda2.001">
        <origin xyz="0 0 0" rpy="0 0 0"/>
        <geometry>
          <mesh filename="../meshes/dae/Torus.003.dae" scale="0.4 0.4 1.0"/>
        </geometry>
      </visual>
      <collision name="rueda2.001.000">
        <origin xyz="0 0 0" rpy="0 0 0"/>
        <geometry>
          <mesh filename="../meshes/dae/Torus.004.dae" scale="1.0 1.0 1.0"/>
        </geometry>
      </collision>
    </link>

    <link name="rueda4">
      <inertial>
        <origin xyz="0 0 0" rpy="0 0 0"/>
        <mass value="0.001"/>
        <inertia ixx="0.001" ixy="0" ixz="0" iyy="0.001" iyz="0" izz="0.001"/>
      </inertial>
      <visual name="rueda1.001">
        <origin xyz="0 0 0" rpy="0 0 0"/>
        <geometry>
          <mesh filename="../meshes/dae/Torus.006.dae" scale="0.4 0.4 1.0"/>
        </geometry>
      </visual>
      <collision name="rueda1.001.000">
        <origin xyz="0 0 0" rpy="0 0 0"/>
        <geometry>
          <mesh filename="../meshes/dae/Torus.002.dae" scale="1.0 1.0 1.0"/>
        </geometry>
      </collision>
    </link>

    <joint name="Untitled" type="prismatic">
      <origin xyz="0 -1.3 1.50313" rpy="0 0 0"/>
      <parent link="coche"/>
      <child link="Untitled"/>
      <axis xyz="0 0 1.0"/>
      <limit lower="0" upper="0" effort="0" velocity="0"/>
    </joint>

    <joint name="Untitled.001" type="floating">
      <origin xyz="-3.07181 -2.04296 -0.35164" rpy="-0.02845 0 -1.5708"/>
      <parent link="Untitled.005"/>
      <child link="Untitled.001"/>
    </joint>

    <joint name="Untitled.002" type="floating">
      <origin xyz="-3.05929 -1.78296 0.08819" rpy="-1.5708 -1.54235 0"/>
      <parent link="Untitled.005"/>
      <child link="Untitled.002"/>
    </joint>

    <joint name="Untitled.003" type="floating">
      <origin xyz="-3.04678 -2.04296 0.52801" rpy="-0.02845 0 -1.5708"/>
      <parent link="Untitled.005"/>
      <child link="Untitled.003"/>
    </joint>

    <joint name="Untitled.004" type="floating">
      <origin xyz="-3.04707 -1.00568 0.08784" rpy="-1.5708 -1.54235 0"/>
      <parent link="Untitled.005"/>
      <child link="Untitled.004"/>
    </joint>

    <joint name="Untitled.005" type="revolute">
      <origin xyz="0.03695 -0.02274 0.42047" rpy="1.5708 0 2.18414"/>
      <parent link="Untitled.006"/>
      <child link="Untitled.005"/>
      <axis xyz="0 0 1.0"/>
      <limit lower="1.5708" upper="0" effort="0" velocity="0"/>
    </joint>

    <joint name="Untitled.006" type="continuous">
      <origin xyz="-0.01713 0.0009 0.84188" rpy="0 0 0"/>
      <parent link="Untitled"/>
      <child link="Untitled.006"/>
      <axis xyz="0 0 1.0"/>
      <limit effort="0" velocity="0"/>
    </joint>

    <joint name="rueda1" type="continuous">
      <origin xyz="1.5 1.47 -1.17" rpy="0 1.5708 0"/>
      <parent link="coche"/>
      <child link="rueda1"/>
      <axis xyz="0 0 1.0"/>
      <limit effort="0" velocity="0"/>
    </joint>

    <joint name="rueda2" type="continuous">
      <origin xyz="1.5 -1.47 -1.17" rpy="0 1.5708 0"/>
      <parent link="coche"/>
      <child link="rueda2"/>
      <axis xyz="0 0 1.0"/>
      <limit effort="0" velocity="0"/>
    </joint>

    <joint name="rueda3" type="continuous">
      <origin xyz="-1.5 1.47 -1.17" rpy="0 1.5708 0"/>
      <parent link="coche"/>
      <child link="rueda3"/>
      <axis xyz="0 0 1.0"/>
      <limit effort="0" velocity="0"/>
    </joint>

    <joint name="rueda4" type="continuous">
      <origin xyz="-1.5 -1.47 -1.17" rpy="0 1.5708 0"/>
      <parent link="coche"/>
      <child link="rueda4"/>
      <axis xyz="0 0 1.0"/>
      <limit effort="0" velocity="0"/>
    </joint>

    <material name="Material">
      <color rgba="0.64 0.64 0.64 1.0"/>
    </material>

  </robot>
