<?xml version="1.0"?>
<!-- created with Phobos 1.0.1 "Capricious Choutengan" -->
  <robot name="robot_nuevo">

    <link name="Untitled.006">
      <inertial>
        <origin xyz="0 0 0" rpy="0 0 0"/>
        <mass value="0.001"/>
        <inertia ixx="0.001" ixy="0" ixz="0" iyy="0.001" iyz="0" izz="0.001"/>
      </inertial>
    </link>

    <link name="Untitled.007">
      <inertial>
        <origin xyz="0 0 0" rpy="0 0 0"/>
        <mass value="0.001"/>
        <inertia ixx="0.001" ixy="0" ixz="0" iyy="0.001" iyz="0" izz="0.001"/>
      </inertial>
    </link>

    <link name="Untitled.008">
      <inertial>
        <origin xyz="0 0 0" rpy="0 0 0"/>
        <mass value="0.001"/>
        <inertia ixx="0.001" ixy="0" ixz="0" iyy="0.001" iyz="0" izz="0.001"/>
      </inertial>
    </link>

    <link name="Untitled.009">
      <inertial>
        <origin xyz="0 0 0" rpy="0 0 0"/>
        <mass value="0.001"/>
        <inertia ixx="0.001" ixy="0" ixz="0" iyy="0.001" iyz="0" izz="0.001"/>
      </inertial>
    </link>

    <link name="coche">
      <inertial>
        <origin xyz="0 0 0" rpy="0 0 0"/>
        <mass value="0.001"/>
        <inertia ixx="0.001" ixy="0" ixz="0" iyy="0.001" iyz="0" izz="0.001"/>
      </inertial>
      <visual name="car">
        <origin xyz="0 0 0" rpy="0 0 0"/>
        <geometry>
          <mesh filename="../meshes/dae/Cube.dae" scale="1.0 1.715 0.78246"/>
        </geometry>
        <material name="Material"/>
      </visual>
    </link>

    <link name="pinzaL">
      <inertial>
        <origin xyz="0 0 0" rpy="0 0 0"/>
        <mass value="0.001"/>
        <inertia ixx="0.001" ixy="0" ixz="0" iyy="0.001" iyz="0" izz="0.001"/>
      </inertial>
    </link>

    <link name="pinzaR">
      <inertial>
        <origin xyz="0 0 0" rpy="0 0 0"/>
        <mass value="0.001"/>
        <inertia ixx="0.001" ixy="0" ixz="0" iyy="0.001" iyz="0" izz="0.001"/>
      </inertial>
    </link>

    <link name="rueda1">
      <inertial>
        <origin xyz="0 0 0" rpy="0 0 0"/>
        <mass value="0.001"/>
        <inertia ixx="0.001" ixy="0" ixz="0" iyy="0.001" iyz="0" izz="0.001"/>
      </inertial>
      <visual name="rueda3.001">
        <origin xyz="0 0 0" rpy="0 0 0"/>
        <geometry>
          <mesh filename="../meshes/dae/Torus.007.dae" scale="0.4 0.4 1.0"/>
        </geometry>
      </visual>
    </link>

    <link name="rueda2">
      <inertial>
        <origin xyz="0 0 0" rpy="0 0 0"/>
        <mass value="0.001"/>
        <inertia ixx="0.001" ixy="0" ixz="0" iyy="0.001" iyz="0" izz="0.001"/>
      </inertial>
      <visual name="rueda4.001">
        <origin xyz="0 0 0" rpy="0 0 0"/>
        <geometry>
          <mesh filename="../meshes/dae/Torus.008.dae" scale="0.4 0.4 1.0"/>
        </geometry>
      </visual>
    </link>

    <link name="rueda3">
      <inertial>
        <origin xyz="0 0 0" rpy="0 0 0"/>
        <mass value="0.001"/>
        <inertia ixx="0.001" ixy="0" ixz="0" iyy="0.001" iyz="0" izz="0.001"/>
      </inertial>
      <visual name="rueda2.001">
        <origin xyz="0 0 0" rpy="0 0 0"/>
        <geometry>
          <mesh filename="../meshes/dae/Torus.003.dae" scale="0.4 0.4 1.0"/>
        </geometry>
      </visual>
    </link>

    <link name="rueda4">
      <inertial>
        <origin xyz="0 0 0" rpy="0 0 0"/>
        <mass value="0.001"/>
        <inertia ixx="0.001" ixy="0" ixz="0" iyy="0.001" iyz="0" izz="0.001"/>
      </inertial>
      <visual name="rueda1.001">
        <origin xyz="0 0 0" rpy="0 0 0"/>
        <geometry>
          <mesh filename="../meshes/dae/Torus.006.dae" scale="0.4 0.4 1.0"/>
        </geometry>
      </visual>
    </link>

    <link name="sphere">
      <inertial>
        <origin xyz="0 0 0" rpy="0 0 0"/>
        <mass value="0.001"/>
        <inertia ixx="0.001" ixy="0" ixz="0" iyy="0.001" iyz="0" izz="0.001"/>
      </inertial>
    </link>

    <joint name="Untitled.006" type="prismatic">
      <origin xyz="0 -1.3 1.59275" rpy="0 0 0"/>
      <parent link="coche"/>
      <child link="Untitled.006"/>
      <axis xyz="0 0 1.0"/>
      <limit lower="0" upper="0" effort="0" velocity="0"/>
    </joint>

    <joint name="Untitled.007" type="floating">
      <origin xyz="0 -1.29238 2.37723" rpy="1.5708 0 0"/>
      <parent link="coche"/>
      <child link="Untitled.007"/>
    </joint>

    <joint name="Untitled.008" type="floating">
      <origin xyz="0 -4.38732 2.26152" rpy="0 0 0"/>
      <parent link="coche"/>
      <child link="Untitled.008"/>
    </joint>

    <joint name="Untitled.009" type="floating">
      <origin xyz="0 -4.38567 1.50827" rpy="0 0 0"/>
      <parent link="coche"/>
      <child link="Untitled.009"/>
    </joint>

    <joint name="pinzaL" type="floating">
      <origin xyz="-0.44 -4.38808 1.25" rpy="0 1.5708 0"/>
      <parent link="coche"/>
      <child link="pinzaL"/>
    </joint>

    <joint name="pinzaR" type="floating">
      <origin xyz="0.44 -4.38578 1.25" rpy="0 1.5708 0"/>
      <parent link="coche"/>
      <child link="pinzaR"/>
    </joint>

    <joint name="rueda1" type="continuous">
      <origin xyz="1.5 1.47 -1.17" rpy="0 1.5708 0"/>
      <parent link="coche"/>
      <child link="rueda1"/>
      <axis xyz="0 0 1.0"/>
      <limit effort="0" velocity="0"/>
    </joint>

    <joint name="rueda2" type="continuous">
      <origin xyz="1.5 -1.47 -1.17" rpy="0 1.5708 0"/>
      <parent link="coche"/>
      <child link="rueda2"/>
      <axis xyz="0 0 1.0"/>
      <limit effort="0" velocity="0"/>
    </joint>

    <joint name="rueda3" type="continuous">
      <origin xyz="-1.5 1.47 -1.17" rpy="0 1.5708 0"/>
      <parent link="coche"/>
      <child link="rueda3"/>
      <axis xyz="0 0 1.0"/>
      <limit effort="0" velocity="0"/>
    </joint>

    <joint name="rueda4" type="continuous">
      <origin xyz="-1.5 -1.47 -1.17" rpy="0 1.5708 0"/>
      <parent link="coche"/>
      <child link="rueda4"/>
      <axis xyz="0 0 1.0"/>
      <limit effort="0" velocity="0"/>
    </joint>

    <joint name="sphere" type="floating">
      <origin xyz="-0.01713 -1.2991 2.34501" rpy="0 0 0"/>
      <parent link="coche"/>
      <child link="sphere"/>
    </joint>

    <material name="Material">
      <color rgba="0.64 0.64 0.64 1.0"/>
    </material>

  </robot>
